Workbook

Sheet heat exchanger 
A1: Heat Exchanger
A5: Shell and tube type
A7: Heat Exchange (Q_kW) | B7: =1500 -> 1500 | J7: 458 kelvin and 2MPA | M7: 383 kelvin and 2MPA
B8: cel | C8: kelvin | F8: water | G8: Hot side fluid | H8: shell side fluid | I8: Parameters | J8: hot side fluid | M8: cold side fluid
A9: T_h,in (T1) | B9: 210 | C9: =B9+273 -> 483 | F9: water | G9: cold side fluid | H9: Tube side fluid | I9: specific heat (cp_(kj/kgk)) | J9: 4.42065 | M9: 4.2257
A10: T_h,out (T2) | B10: 160 | C10: =B10+273 -> 433 | I10: Density (rho_(kg/m3)) | J10: 988.2324 | M10: 951.9588
A11: T_c,in (t1) | B11: 110 | C11: =B11+273 -> 383 | I11: specific Volume (v_(m3/kg)) | J11: =1.1723/1000 -> 0.0011723 | M11: =1.0505/1000 -> 0.0010505
A12: T_c,out (t2) | B12: 150 | C12: =B12+273 -> 423 | I12: thermal conductivity | J12: 0.66956 | M12: 0.68404
A13: Th,mean | B13: =(B9+B10)/2 -> 185 | C13: =(C9+C10)/2 -> 458 | I13: Dynamic viscosity | J13: 0.000146439 | M13: 0.000213657
A14: Tc,mean | B14: =((B11+B12)/2) -> 130 | C14: =((C11+C12)/2) -> 403
A16: Assume Pressure as 2MPA | E16: Considering the overall heat transfer coeffiecent | F16: 600 | J16: user input
J17: user output
A18: m,hot | B18: =(B7/(J9*(B9-B10))) -> 6.7863323 | C18: kg/sec
A19: m,cold | B19: =(B7/(M9*(B12-B11))) -> 8.8742694 | C19: kg/sec
A21: LMTD calculation _counter flow
A22: T1 | B22: =B9-B12 -> 60 | E22: R (from formula) | F22: =(B9-B10)/(B12-B11) -> 1.25
A23: T2 | B23: =B10-B11 -> 50 | E23: S (from formula) | F23: =(B12-B11)/(B9-B11) -> 0.4
A24: T_LMTD | B24: =(B22-B23)/LN(B22/B23) -> 54.848149 | E24: R-1 | F24: =F22-1 -> 0.25
E25: 1-S | F25: =1-F23 -> 0.6
A26: Correction factor | E26: 1-RS | F26: =(1-(F22*F23)) -> 0.5
A27: numerator | B27: =F27*LN(F25/F26) -> 0.29185689 | E27: ((R^2)+1)^(1/2) | F27: =((F22^2)+1)^(1/2) -> 1.6007811
B28: =(2-(($F$23*($F$22+1-$F$27)))) -> 1.7403124
B29: =(2-(($F$23*($F$22+1+$F$27)))) -> 0.45968758
A30: ln | B30: =F24*(LN(B28/B29)) -> 0.33281821
A31: Fₜ (correction factor) | B31: =(B27/B30) -> 0.87692585
A32: Corretected LMTD factor | B32: =B31*B24 -> 48.09776
A34: Heat transfer Area
A36: Area (m2) | B36: =(B7*1000)/(F16*B32) -> 51.977472
A38: Tube Geometry | G38: Tube Materials
A39: Diameter | G39: Materials | H39: Thermal Conductivity
A40: mm | B40: 22.2 | C40: 2 | D40: outer diameter (mm) | E40: 22.2 | G40: k ≈ 45 W/m·K | H40: Carbon Steel | I40: 45
A41: m | B41: =B40/1000 -> 0.0222 | D41: Inner diameter (mm) | E41: 19.9 | F41: 1 | G41: k ≈ 16 W/m·k | H41: Stainless Steel 304 | I41: 16
A42: area(m2) | B42: =(PI()*B41*B43) -> 0.17017379 | G42: k ≈ 111 W/m·K | H42: Admiralty Brass | I42: 111
A43: tube length(m) | B43: 2.44 | D43: industrial tube size OD | E43: {=INDEX(Sheet1!D2:D20,MATCH('heat exchanger '!B40,Sheet1!D2:D20,1)+1)} -> 28.6 | G43: k ≈ 385 W/m·K | H43: Copper | I43: 385
A44: tube thickness(mm) | B44: =(E40-E41)/2 -> 1.15 | D44: industrial tube size ID | E44: =INDEX(Sheet1!F2:F20,MATCH('heat exchanger '!E43,Sheet1!D2:D20,0)) -> 26 | G44: k ≈ 21 W/m·K | H44: Monel 400 | I44: 21
A45: number of tubes | B45: =(B36/B42) -> 305.43759 | C45: =ROUNDUP(B45,0.1) -> 306 | D45: industrial tube thickness | E45: =INDEX(Sheet1!H2:H20,MATCH('heat exchanger '!E43,Sheet1!D2:D20,0)) -> 1.27 | G45: k ≈ 9.5 W/m·K | H45: Titanium | I45: 9.5
A46: tube pitch | B46: =27/1000 -> 0.027 | G46: k ≈ 17 W/m·K | H46: Inconel 600 | I46: 17
A47: pitch | B47: triangular | C47: square
A48: no of pass | B48: 2 | C48: 2
A49: k1 constant | B49: =INDEX(K55:O55,MATCH(B48,K54:O54,0)) -> 0.249 | C49: =INDEX(K58:O58,MATCH(C48,K54:O54,0)) -> 0.156
...

Sheet shell dimension
A1: AESTEIRON PIPE DIMENSIONS & WEIGHTS TO ASME B36.10 / B36.19
A3: NOMINAL PIPE SIZE | C3: OD | E3: SCHEDULE DESIGNATIONS (ASME) | F3: WALL THICKNESS | H3: ID | J3: WEIGHT
A4: INCH | B4: MM | C4: INCH | D4: MM | E4: ASME | F4: INCH | G4: MM | H4: INCH | I4: MM | J4: LBS/FOOT | K4: KG/METER
A5: 12 | B5: 300 | C5: 12.75 | D5: 323.8 | E5: 5S | F5: 0.156 | G5: 3.96 | H5: 12.438 | I5: 315.88 | J5: 21 | K5: 31.24
E6: 10S | F6: 0.18 | G6: 4.57 | H6: 12.39 | I6: 314.66 | J6: 24.19 | K6: 35.98
E7: - | F7: 0.188 | G7: 4.78 | H7: 12.374 | I7: 314.24 | J7: 25.25 | K7: 37.61
E8: 20 | F8: 0.25 | G8: 6.35 | H8: 12.25 | I8: 311.1 | J8: 33.41 | K8: 49.71
E9: 30 | F9: 0.33 | G9: 8.38 | H9: 12.09 | I9: 307.04 | J9: 43.81 | K9: 65.19
E10: STD / 40S | F10: 0.375 | G10: 9.53 | H10: 12 | I10: 304.74 | J10: 49.61 | K10: 73.86
E11: 40 | F11: 0.406 | G11: 10.31 | H11: 11.938 | I11: 303.18 | J11: 53.57 | K11: 79.71
E12: XS / 80S | F12: 0.5 | G12: 12.7 | H12: 11.75 | I12: 298.4 | J12: 65.48 | K12: 97.44
E13: 60 | F13: 0.562 | G13: 14.27 | H13: 11.626 | I13: 295.26 | J13: 73.22 | K13: 108.93
E14: 80 | F14: 0.688 | G14: 17.48 | H14: 11.374 | I14: 288.84 | J14: 88.71 | K14: 132.05
E15: 100 | F15: 0.844 | G15: 21.44 | H15: 11.062 | I15: 280.92 | J15: 107.42 | K15: 159.87
E16: 120 | F16: 1 | G16: 25.4 | H16: 10.75 | I16: 273 | J16: 125.61 | K16: 186.92
E17: 140 / XX | F17: 1.125 | G17: 28.58 | H17: 10.5 | I17: 266.64 | J17: 139.81 | K17: 208.08
E18: 160 | F18: 1.312 | G18: 33.32 | H18: 10.126 | I18: 257.16 | J18: 160.42 | K18: 238.69
A19: 14 | B19: 350 | C19: 14 | D19: 355.6 | E19: 10S | F19: 0.188 | G19: 4.78 | H19: 13.624 | I19: 346.04 | J19: 27.76 | K19: 41.36
E20: 10 | F20: 0.25 | G20: 6.35 | H20: 13.5 | I20: 342.9 | J20: 36.75 | K20: 54.69
E21: 20 | F21: 0.312 | G21: 7.92 | H21: 13.376 | I21: 339.76 | J21: 45.65 | K21: 67.91
E22: STD / 30 / 40S | F22: 0.375 | G22: 9.53 | H22: 13.25 | I22: 336.54 | J22: 54.62 | K22: 81.33
E23: 40 | F23: 0.438 | G23: 11.13 | H23: 13.124 | I23: 333.34 | J23: 63.5 | K23: 94.55
E24: XS / 80S | F24: 0.5 | G24: 12.7 | H24: 13 | I24: 330.2 | J24: 72.16 | K24: 107.4
E25: 60 | F25: 0.594 | G25: 15.09 | H25: 12.812 | I25: 325.42 | J25: 85.13 | K25: 126.72
E26: 80 | F26: 0.75 | G26: 19.05 | H26: 12.5 | I26: 317.5 | J26: 106.23 | K26: 158.11
E27: 100 | F27: 0.938 | G27: 23.83 | H27: 12.124 | I27: 307.94 | J27: 130.98 | K27: 194.98
E28: 120 | F28: 1.094 | G28: 27.79 | H28: 11.812 | I28: 300.02 | J28: 150.93 | K28: 224.66
E29: 140 | F29: 1.25 | G29: 31.75 | H29: 11.5 | I29: 292.1 | J29: 170.37 | K29: 253.58
E30: 160 | F30: 1.406 | G30: 35.71 | H30: 11.188 | I30: 284.18 | J30: 189.29 | K30: 281.72
A31: 16 | B31: 400 | C31: 16 | D31: 406.4 | E31: 10S | F31: 0.188 | G31: 4.78 | H31: 15.624 | I31: 396.84 | J31: 31.78 | K31: 47.34
E32: 10 | F32: 0.25 | G32: 6.35 | H32: 15.5 | I32: 393.7 | J32: 42.09 | K32: 62.65
E33: 20 | F33: 0.312 | G33: 7.92 | H33: 15.376 | I33: 390.56 | J33: 52.32 | K33: 77.83
E34: STD / 40S | F34: 0.375 | G34: 9.53 | H34: 15.25 | I34: 390.34 | J34: 62.64 | K34: 93.27
E35: 40 / XS | F35: 0.5 | G35: 12.7 | H35: 15 | I35: 381 | J35: 82.85 | K35: 123.31
E36: 60 / 80S | F36: 0.656 | G36: 16.66 | H36: 14.688 | I36: 373.08 | J36: 107.6 | K36: 160.13
E37: 80 | F37: 0.844 | G37: 21.44 | H37: 14.312 | I37: 363.52 | J37: 136.74 | K37: 203.54
E38: 100 | F38: 1.031 | G38: 26.19 | H38: 13.938 | I38: 354.02 | J38: 164.98 | K38: 245.57
E39: 120 | F39: 1.219 | G39: 30.96 | H39: 13.562 | I39: 344.48 | J39: 192.61 | K39: 286.66
E40: 140 | F40: 1.438 | G40: 36.53 | H40: 13.124 | I40: 333.34 | J40: 223.85 | K40: 333.21
E41: 160 | F41: 1.594 | G41: 40.49 | H41: 12.812 | I41: 325.42 | J41: 245.48 | K41: 365.38
...

Sheet brass chart
A1: Thickness | B1: Length x Width | E1: Thickness
B2: 1200 x 600 mm | C2: 4ft x 2ft | D2: 2000 x 1000 mm
A3: 0.7 mm | B3: 4.309 | C3: 4.448 | D3: 11.97 | E3: 0.7
A4: 0.9 mm | B4: 5.54 | C4: 5.719 | D4: 15.39 | E4: 0.9
A5: 1.0 mm | B5: 6.156 | C5: 6.355 | D5: 17.1 | E5: 1
A6: 1.2 mm | B6: 7.387 | C6: 7.625 | D6: 20.52 | E6: 1.2
A7: 1.5 mm | B7: 9.234 | C7: 9.532 | D7: 25.65 | E7: 1.5
A8: 1.6 mm | B8: 9.85 | C8: 10.167 | D8: 27.36 | E8: 1.6
A9: 2.0 mm | B9: 12.312 | C9: 12.709 | D9: 34.2 | E9: 2
A10: 2.5 mm | B10: 15.39 | C10: 15.886 | D10: 42.75 | E10: 2.5
A11: 3.0 mm | B11: 18.468 | C11: 19.064 | D11: 51.3 | E11: 3
A12: 3/16 ins | B12: 29.318 | C12: 30.264 | D12: 81.439 | E12: 4.76
A13: 1/4 ins | B13: 39.091 | C13: 40.352 | D13: 108.585 | E13: 6.35
A14: 5/16 ins | B14: 48.863 | C14: 50.439 | D14: - | E14: 7.94
A15: 3/8 ins | B15: 58.636 | C15: 60.527 | D15: - | E15: 9.53
A16: 1/2 ins | B16: 78.181 | C16: 80.703 | D16: - | E16: 12.7
A17: 5/8 ins | B17: 97.727 | C17: 100.879 | D17: - | E17: 15.88
A18: 3/4 ins | B18: 117.272 | C18: 121.055 | D18: - | E18: 19.05
A19: 1 ins | B19: 156.362 | C19: 161.406 | D19: - | E19: 25.4
A20: 1 1/4 ins | B20: 195.453 | C20: 201.758 | D20: - | E20: 31.75
A21: 1 1/2 ins | B21: 234.544 | C21: 242.109 | D21: - | E21: 38.1
A22: 1 3/4 ins | B22: 273.634 | C22: 282.461 | D22: - | E22: 44.45
A23: 2 ins | B23: 312.725 | C23: 322.812 | D23: - | E23: 50.8

Sheet Sheet1
A1: Nominal Size (in) | B1: Temper | C1: Outside Diameter (in) | D1: Outside Diameter (mm) | E1: Inside Diameter (in) | F1: Inside Diameter (mm) | G1: Wall Thickness (in) | H1: Wall Thickness (mm) | I1: Bore Cross Section Area (in2)
A2: 46235 | B2: A | C2: 0.125 | D2: 3.18 | E2: 0.065 | F2: 1.65 | G2: 0.03 | H2: 0.762 | I2: 0.0033
A3: 42430 | B3: A | C3: 0.187 | D3: 4.75 | E3: 0.128 | F3: 3.25 | G3: 0.03 | H3: 0.762 | I3: 0.0129
A4: 46113 | B4: A | C4: 0.25 | D4: 6.35 | E4: 0.19 | F4: 4.83 | G4: 0.03 | H4: 0.762 | I4: 0.0284
A5: 42491 | B5: A | C5: 0.312 | D5: 7.92 | E5: 0.248 | F5: 6.3 | G5: 0.032 | H5: 0.813 | I5: 0.0483
A6: 46237 | B6: A | C6: 0.375 | D6: 9.52 | E6: 0.311 | F6: 7.9 | G6: 0.032 | H6: 0.813 | I6: 0.076
B7: D | C7: 0.375 | D7: 9.52 | E7: 0.315 | F7: 8 | G7: 0.03 | H7: 0.762 | I7: 0.078
A8: 46054 | B8: A | C8: 0.5 | D8: 12.7 | E8: 0.436 | F8: 11.1 | G8: 0.032 | H8: 0.813 | I8: 0.149
B9: D | C9: 0.5 | D9: 12.7 | E9: 0.43 | F9: 10.9 | G9: 0.035 | H9: 0.889 | I9: 0.145
A10: 46239 | B10: A | C10: 0.625 | D10: 15.9 | E10: 0.555 | F10: 14.1 | G10: 0.035 | H10: 0.889 | I10: 0.242
B11: D | C11: 0.625 | D11: 15.9 | E11: 0.545 | F11: 13.8 | G11: 0.04 | H11: 1.02 | I11: 0.233
A12: 46115 | B12: A | C12: 0.75 | D12: 19 | E12: 0.68 | F12: 17.3 | G12: 0.035 | H12: 0.889 | I12: 0.363
B13: A | C13: 0.75 | D13: 19 | E13: 0.666 | F13: 16.9 | G13: 0.042 | H13: 1.07 | I13: 0.348
B14: D | C14: 0.75 | D14: 19 | E14: 0.666 | F14: 16.9 | G14: 0.042 | H14: 1.07 | I14: 0.348
A15: 46241 | B15: A | C15: 0.875 | D15: 22.2 | E15: 0.785 | F15: 19.9 | G15: 0.045 | H15: 1.14 | I15: 0.484
B16: D | C16: 0.875 | D16: 22.2 | E16: 0.785 | F16: 19.9 | G16: 0.045 | H16: 1.14 | I16: 0.484
A17: 1.125 | B17: A | C17: 1.125 | D17: 28.6 | E17: 1.025 | F17: 26 | G17: 0.05 | H17: 1.27 | I17: 0.825
B18: D | C18: 1.125 | D18: 28.6 | E18: 1.025 | F18: 26 | G18: 0.05 | H18: 1.27 | I18: 0.825
A19: 1.375 | B19: A | C19: 1.375 | D19: 34.9 | E19: 1.265 | F19: 32.1 | G19: 0.055 | H19: 1.41 | I19: 1.26
B20: D | C20: 1.375 | D20: 34.9 | E20: 1.265 | F20: 32.1 | G20: 0.055 | H20: 1.41 | I20: 1.26

Sheet Sheet2
A1: ASME B16.5 Flange Dimensions Master Table
A3: Pressure Class | B3: NPS (Nominal Pipe Size) | C3: O - Flange OD (mm) | D3: tf - Flange Thickness (mm) | E3: ID - Flange ID (mm)
A4: 150# | B4: 1/2 | C4: 89 | D4: 9.6 | E4: 34.9
A5: 150# | B5: 3/4 | C5: 99 | D5: 11.2 | E5: 42.9
A6: 150# | B6: 1 | C6: 108 | D6: 12.7 | E6: 50.8
A7: 150# | B7: 1-1/4 | C7: 117 | D7: 14.2 | E7: 63.5
A8: 150# | B8: 1-1/2 | C8: 127 | D8: 15.9 | E8: 73
A9: 150# | B9: 2 | C9: 152 | D9: 17.5 | E9: 92.1
A10: 150# | B10: 2-1/2 | C10: 178 | D10: 20.7 | E10: 104.8
A11: 150# | B11: 3 | C11: 190 | D11: 22.4 | E11: 127
A12: 150# | B12: 3-1/2 | C12: 216 | D12: 22.4 | E12: 139.7
A13: 150# | B13: 4 | C13: 229 | D13: 22.4 | E13: 157.2
A14: 150# | B14: 5 | C14: 254 | D14: 22.4 | E14: 185.7
A15: 150# | B15: 6 | C15: 279 | D15: 23.9 | E15: 215.7
... A24: 300# | B24: 1/2 | C24: 95 | D24: 12.7 | E24: 34.9
A25: 300# | B25: 3/4 | C25: 115 | D25: 14.3
A26: 300# | B26: 1 | C26: 125 | D26: 15.9
A27: 300# | B27: 1-1/4 | C27: 135 | D27: 17.5
A28: 300# | B28: 1-1/2 | C28: 155 | D28: 19.1
A29: 300# | B29: 2 | C29: 165 | D29: 20.7
A30: 300# | B30: 2-1/2 | C30: 190 | D30: 23.9
A31: 300# | B31: 3 | C31: 210 | D31: 27
A32: 300# | B32: 3-1/2 | C32: 230 | D32: 28.6
A33: 300# | B33: 4 | C33: 255 | D33: 30.2
A34: 300# | B34: 5 | C34: 280 | D34: 33.4
A35: 300# | B35: 6 | C35: 320 | D35: 35
A36: 300# | B36: 8 | C36: 380 | D36: 39.7
... A135: 2500# | B135: 12 | C135: 760 | D135: 184.2

Sheet Sheet3
